2024-01-05 20:28:07,118 INFO    MainThread:4167 [wandb_setup.py:_flush():68] Configure stats pid to 4167
2024-01-05 20:28:07,119 INFO    MainThread:4167 [wandb_setup.py:_flush():68] Loading settings from /home/paperspace/.config/wandb/settings
2024-01-05 20:28:07,119 INFO    MainThread:4167 [wandb_setup.py:_flush():68] Loading settings from /home/paperspace/Documents/plant_pathology/notebooks/wandb/settings
2024-01-05 20:28:07,119 INFO    MainThread:4167 [wandb_setup.py:_flush():68] Loading settings from environment variables: {'_require_service': 'True'}
2024-01-05 20:28:07,119 INFO    MainThread:4167 [wandb_setup.py:_flush():68] Inferring run settings from compute environment: {'program': '<python with no main file>'}
2024-01-05 20:28:07,119 INFO    MainThread:4167 [wandb_init.py:_log_setup():476] Logging user logs to /home/paperspace/Documents/plant_pathology/notebooks/wandb/run-20240105_202807-3clbr1k4/logs/debug.log
2024-01-05 20:28:07,119 INFO    MainThread:4167 [wandb_init.py:_log_setup():477] Logging internal logs to /home/paperspace/Documents/plant_pathology/notebooks/wandb/run-20240105_202807-3clbr1k4/logs/debug-internal.log
2024-01-05 20:28:07,119 INFO    MainThread:4167 [wandb_init.py:init():516] calling init triggers
2024-01-05 20:28:07,119 INFO    MainThread:4167 [wandb_init.py:init():519] wandb.init called with sweep_config: {}
config: {'model_name': 'incep_v1', 'dataset_name': 'plant_pathology', 'epochs': 50, 'batch_size': 512, 'num_workers': 10, 'learning_rate': 0.001, 'optimizer': 'Adam', 'weights_path': '../../weights/incep_v1_hflip_rrotate/', 'normalize': True}
2024-01-05 20:28:07,119 INFO    MainThread:4167 [wandb_init.py:init():535] re-initializing run, found existing run on stack: 1rdzyp56
2024-01-05 20:28:07,120 INFO    MainThread:4167 [wandb_run.py:_finish():1746] finishing run yashchks87/plant_pathology/1rdzyp56
2024-01-05 20:28:07,120 INFO    MainThread:4167 [jupyter.py:save_history():448] not saving jupyter history
2024-01-05 20:28:07,120 INFO    MainThread:4167 [jupyter.py:save_ipynb():378] not saving jupyter notebook
2024-01-05 20:28:07,120 INFO    MainThread:4167 [wandb_init.py:_jupyter_teardown():408] cleaning up jupyter logic
2024-01-05 20:28:07,120 INFO    MainThread:4167 [wandb_run.py:_atexit_cleanup():1949] got exitcode: 0
2024-01-05 20:28:07,121 INFO    MainThread:4167 [wandb_run.py:_restore():1932] restore
2024-01-05 20:28:07,121 INFO    MainThread:4167 [wandb_run.py:_restore():1938] restore done
2024-01-05 20:28:13,008 INFO    MainThread:4167 [wandb_init.py:init():569] starting backend
2024-01-05 20:28:13,008 INFO    MainThread:4167 [wandb_init.py:init():573] setting up manager
2024-01-05 20:28:13,009 INFO    MainThread:4167 [backend.py:_multiprocessing_setup():102] multiprocessing start_methods=fork,spawn,forkserver, using: spawn
2024-01-05 20:28:13,010 INFO    MainThread:4167 [wandb_init.py:init():580] backend started and connected
2024-01-05 20:28:13,014 INFO    MainThread:4167 [wandb_run.py:_label_probe_notebook():1113] probe notebook
2024-01-05 20:28:13,014 INFO    MainThread:4167 [wandb_run.py:_label_probe_notebook():1123] Unable to probe notebook: 'NoneType' object has no attribute 'get'
2024-01-05 20:28:13,014 INFO    MainThread:4167 [wandb_init.py:init():658] updated telemetry
2024-01-05 20:28:13,072 INFO    MainThread:4167 [wandb_init.py:init():693] communicating run to backend with 60 second timeout
2024-01-05 20:28:17,683 WARNING MsgRouterThr:4167 [router.py:message_loop():77] message_loop has been closed
2024-01-05 20:28:17,684 WARNING MsgRouterThr:4167 [router.py:message_loop():77] message_loop has been closed
2024-01-05 20:28:18,084 ERROR   MainThread:4167 [wandb_init.py:init():1105] error
Traceback (most recent call last):
  File "/home/paperspace/.local/lib/python3.9/site-packages/wandb/sdk/wandb_init.py", line 1078, in init
    run = wi.init()
  File "/home/paperspace/.local/lib/python3.9/site-packages/wandb/sdk/wandb_init.py", line 697, in init
    result = handle.wait(
  File "/home/paperspace/.local/lib/python3.9/site-packages/wandb/sdk/lib/mailbox.py", line 259, in wait
    raise MailboxError("transport failed")
wandb.errors.MailboxError: transport failed
2024-01-05 20:28:23,313 INFO    MainThread:4167 [wandb_setup.py:_flush():68] Configure stats pid to 4167
2024-01-05 20:28:23,313 INFO    MainThread:4167 [wandb_setup.py:_flush():68] Loading settings from /home/paperspace/.config/wandb/settings
2024-01-05 20:28:23,313 INFO    MainThread:4167 [wandb_setup.py:_flush():68] Loading settings from /home/paperspace/Documents/plant_pathology/notebooks/wandb/settings
2024-01-05 20:28:23,313 INFO    MainThread:4167 [wandb_setup.py:_flush():68] Loading settings from environment variables: {'_require_service': 'True'}
2024-01-05 20:28:23,313 INFO    MainThread:4167 [wandb_setup.py:_flush():68] Inferring run settings from compute environment: {'program': '<python with no main file>'}
2024-01-05 20:28:23,313 INFO    MainThread:4167 [wandb_init.py:_log_setup():476] Logging user logs to /home/paperspace/Documents/plant_pathology/notebooks/wandb/run-20240105_202823-38jx4obu/logs/debug.log
2024-01-05 20:28:23,313 INFO    MainThread:4167 [wandb_init.py:_log_setup():477] Logging internal logs to /home/paperspace/Documents/plant_pathology/notebooks/wandb/run-20240105_202823-38jx4obu/logs/debug-internal.log
2024-01-05 20:28:23,313 INFO    MainThread:4167 [wandb_init.py:_jupyter_setup():426] configuring jupyter hooks <wandb.sdk.wandb_init._WandbInit object at 0x7f87f2ac61c0>
2024-01-05 20:28:23,313 INFO    MainThread:4167 [wandb_init.py:init():516] calling init triggers
2024-01-05 20:28:23,313 INFO    MainThread:4167 [wandb_init.py:init():519] wandb.init called with sweep_config: {}
config: {'model_name': 'incep_v1', 'dataset_name': 'plant_pathology', 'epochs': 50, 'batch_size': 512, 'num_workers': 10, 'learning_rate': 0.001, 'optimizer': 'Adam', 'weights_path': '../../weights/incep_v1_hflip_rrotate_v1/', 'normalize': True}
2024-01-05 20:28:23,313 INFO    MainThread:4167 [wandb_init.py:init():569] starting backend
2024-01-05 20:28:23,313 INFO    MainThread:4167 [wandb_init.py:init():573] setting up manager
2024-01-05 20:28:23,322 ERROR   MainThread:4167 [wandb_init.py:init():1105] error
Traceback (most recent call last):
  File "/home/paperspace/.local/lib/python3.9/site-packages/wandb/sdk/wandb_init.py", line 1078, in init
    run = wi.init()
  File "/home/paperspace/.local/lib/python3.9/site-packages/wandb/sdk/wandb_init.py", line 574, in init
    manager._inform_init(settings=self.settings, run_id=self.settings.run_id)
  File "/home/paperspace/.local/lib/python3.9/site-packages/wandb/sdk/wandb_manager.py", line 170, in _inform_init
    svc_iface._svc_inform_init(settings=settings, run_id=run_id)
  File "/home/paperspace/.local/lib/python3.9/site-packages/wandb/sdk/service/service_sock.py", line 38, in _svc_inform_init
    self._sock_client.send(inform_init=inform_init)
  File "/home/paperspace/.local/lib/python3.9/site-packages/wandb/sdk/lib/sock_client.py", line 211, in send
    self.send_server_request(server_req)
  File "/home/paperspace/.local/lib/python3.9/site-packages/wandb/sdk/lib/sock_client.py", line 155, in send_server_request
    self._send_message(msg)
  File "/home/paperspace/.local/lib/python3.9/site-packages/wandb/sdk/lib/sock_client.py", line 152, in _send_message
    self._sendall_with_error_handle(header + data)
  File "/home/paperspace/.local/lib/python3.9/site-packages/wandb/sdk/lib/sock_client.py", line 130, in _sendall_with_error_handle
    sent = self._sock.send(data)
BrokenPipeError: [Errno 32] Broken pipe
2024-01-05 20:28:32,100 INFO    MainThread:4167 [wandb_setup.py:_flush():68] Configure stats pid to 4167
2024-01-05 20:28:32,101 INFO    MainThread:4167 [wandb_setup.py:_flush():68] Loading settings from /home/paperspace/.config/wandb/settings
2024-01-05 20:28:32,101 INFO    MainThread:4167 [wandb_setup.py:_flush():68] Loading settings from /home/paperspace/Documents/plant_pathology/notebooks/wandb/settings
2024-01-05 20:28:32,101 INFO    MainThread:4167 [wandb_setup.py:_flush():68] Loading settings from environment variables: {'_require_service': 'True'}
2024-01-05 20:28:32,101 INFO    MainThread:4167 [wandb_setup.py:_flush():68] Inferring run settings from compute environment: {'program': '<python with no main file>'}
2024-01-05 20:28:32,101 INFO    MainThread:4167 [wandb_init.py:_log_setup():476] Logging user logs to /home/paperspace/Documents/plant_pathology/notebooks/wandb/run-20240105_202832-vqfnvrux/logs/debug.log
2024-01-05 20:28:32,101 INFO    MainThread:4167 [wandb_init.py:_log_setup():477] Logging internal logs to /home/paperspace/Documents/plant_pathology/notebooks/wandb/run-20240105_202832-vqfnvrux/logs/debug-internal.log
2024-01-05 20:28:32,101 INFO    MainThread:4167 [wandb_init.py:init():516] calling init triggers
2024-01-05 20:28:32,101 INFO    MainThread:4167 [wandb_init.py:init():519] wandb.init called with sweep_config: {}
config: {'model_name': 'incep_v1', 'dataset_name': 'plant_pathology', 'epochs': 50, 'batch_size': 512, 'num_workers': 10, 'learning_rate': 0.001, 'optimizer': 'Adam', 'weights_path': '../../weights/incep_v1_hflip_rrotate_v1/', 'normalize': True}
2024-01-05 20:28:32,101 INFO    MainThread:4167 [wandb_init.py:init():569] starting backend
2024-01-05 20:28:32,101 INFO    MainThread:4167 [wandb_init.py:init():573] setting up manager
2024-01-05 20:28:32,107 ERROR   MainThread:4167 [wandb_init.py:init():1105] error
Traceback (most recent call last):
  File "/home/paperspace/.local/lib/python3.9/site-packages/wandb/sdk/wandb_init.py", line 1078, in init
    run = wi.init()
  File "/home/paperspace/.local/lib/python3.9/site-packages/wandb/sdk/wandb_init.py", line 574, in init
    manager._inform_init(settings=self.settings, run_id=self.settings.run_id)
  File "/home/paperspace/.local/lib/python3.9/site-packages/wandb/sdk/wandb_manager.py", line 170, in _inform_init
    svc_iface._svc_inform_init(settings=settings, run_id=run_id)
  File "/home/paperspace/.local/lib/python3.9/site-packages/wandb/sdk/service/service_sock.py", line 38, in _svc_inform_init
    self._sock_client.send(inform_init=inform_init)
  File "/home/paperspace/.local/lib/python3.9/site-packages/wandb/sdk/lib/sock_client.py", line 211, in send
    self.send_server_request(server_req)
  File "/home/paperspace/.local/lib/python3.9/site-packages/wandb/sdk/lib/sock_client.py", line 155, in send_server_request
    self._send_message(msg)
  File "/home/paperspace/.local/lib/python3.9/site-packages/wandb/sdk/lib/sock_client.py", line 152, in _send_message
    self._sendall_with_error_handle(header + data)
  File "/home/paperspace/.local/lib/python3.9/site-packages/wandb/sdk/lib/sock_client.py", line 130, in _sendall_with_error_handle
    sent = self._sock.send(data)
BrokenPipeError: [Errno 32] Broken pipe
2024-01-05 20:28:48,116 INFO    MainThread:4167 [wandb_setup.py:_flush():68] Configure stats pid to 4167
2024-01-05 20:28:48,116 INFO    MainThread:4167 [wandb_setup.py:_flush():68] Loading settings from /home/paperspace/.config/wandb/settings
2024-01-05 20:28:48,117 INFO    MainThread:4167 [wandb_setup.py:_flush():68] Loading settings from /home/paperspace/Documents/plant_pathology/notebooks/wandb/settings
2024-01-05 20:28:48,117 INFO    MainThread:4167 [wandb_setup.py:_flush():68] Loading settings from environment variables: {'_require_service': 'True'}
2024-01-05 20:28:48,117 INFO    MainThread:4167 [wandb_setup.py:_flush():68] Inferring run settings from compute environment: {'program': '<python with no main file>'}
2024-01-05 20:28:48,117 INFO    MainThread:4167 [wandb_init.py:_log_setup():476] Logging user logs to /home/paperspace/Documents/plant_pathology/notebooks/wandb/run-20240105_202848-1g2r2ukv/logs/debug.log
2024-01-05 20:28:48,117 INFO    MainThread:4167 [wandb_init.py:_log_setup():477] Logging internal logs to /home/paperspace/Documents/plant_pathology/notebooks/wandb/run-20240105_202848-1g2r2ukv/logs/debug-internal.log
2024-01-05 20:28:48,117 INFO    MainThread:4167 [wandb_init.py:init():516] calling init triggers
2024-01-05 20:28:48,117 INFO    MainThread:4167 [wandb_init.py:init():519] wandb.init called with sweep_config: {}
config: {'model_name': 'incep_v1', 'dataset_name': 'plant_pathology', 'epochs': 50, 'batch_size': 512, 'num_workers': 10, 'learning_rate': 0.001, 'optimizer': 'Adam', 'weights_path': '../../weights/incep_v1_hflip_rrotate_v1/', 'normalize': True}
2024-01-05 20:28:48,117 INFO    MainThread:4167 [wandb_init.py:init():569] starting backend
2024-01-05 20:28:48,117 INFO    MainThread:4167 [wandb_init.py:init():573] setting up manager
2024-01-05 20:28:48,123 ERROR   MainThread:4167 [wandb_init.py:init():1105] error
Traceback (most recent call last):
  File "/home/paperspace/.local/lib/python3.9/site-packages/wandb/sdk/wandb_init.py", line 1078, in init
    run = wi.init()
  File "/home/paperspace/.local/lib/python3.9/site-packages/wandb/sdk/wandb_init.py", line 574, in init
    manager._inform_init(settings=self.settings, run_id=self.settings.run_id)
  File "/home/paperspace/.local/lib/python3.9/site-packages/wandb/sdk/wandb_manager.py", line 170, in _inform_init
    svc_iface._svc_inform_init(settings=settings, run_id=run_id)
  File "/home/paperspace/.local/lib/python3.9/site-packages/wandb/sdk/service/service_sock.py", line 38, in _svc_inform_init
    self._sock_client.send(inform_init=inform_init)
  File "/home/paperspace/.local/lib/python3.9/site-packages/wandb/sdk/lib/sock_client.py", line 211, in send
    self.send_server_request(server_req)
  File "/home/paperspace/.local/lib/python3.9/site-packages/wandb/sdk/lib/sock_client.py", line 155, in send_server_request
    self._send_message(msg)
  File "/home/paperspace/.local/lib/python3.9/site-packages/wandb/sdk/lib/sock_client.py", line 152, in _send_message
    self._sendall_with_error_handle(header + data)
  File "/home/paperspace/.local/lib/python3.9/site-packages/wandb/sdk/lib/sock_client.py", line 130, in _sendall_with_error_handle
    sent = self._sock.send(data)
BrokenPipeError: [Errno 32] Broken pipe
